{"level":"ERROR","location":"[get_call:111] fyersModel","message":"('Connection aborted.', ConnectionResetError(10054, 'An existing connection was forcibly closed by the remote host', None, 10054, None))","timestamp":"2024-01-15 09:26:43,679+0530","service":"FyersDataSocket"}
{"level":"ERROR","location":"[get_call:111] fyersModel","message":"('Connection aborted.', ConnectionResetError(10054, 'An existing connection was forcibly closed by the remote host', None, 10054, None))","timestamp":"2024-01-15 09:26:54,143+0530","service":"FyersDataSocket"}
{"level":"ERROR","location":"[get_call:111] fyersModel","message":"('Connection aborted.', ConnectionResetError(10054, 'An existing connection was forcibly closed by the remote host', None, 10054, None))","timestamp":"2024-01-15 09:26:54,160+0530","service":"FyersDataSocket"}
{"level":"ERROR","location":"[get_call:111] fyersModel","message":"('Connection aborted.', ConnectionResetError(10054, 'An existing connection was forcibly closed by the remote host', None, 10054, None))","timestamp":"2024-01-15 09:26:54,160+0530","service":"FyersDataSocket"}
{"level":"ERROR","location":"[get_call:111] fyersModel","message":"('Connection aborted.', ConnectionResetError(10054, 'An existing connection was forcibly closed by the remote host', None, 10054, None))","timestamp":"2024-01-15 09:26:54,160+0530","service":"FyersDataSocket"}
{"level":"ERROR","location":"[get_call:111] fyersModel","message":"('Connection aborted.', ConnectionResetError(10054, 'An existing connection was forcibly closed by the remote host', None, 10054, None))","timestamp":"2024-01-15 09:26:56,809+0530","service":"FyersDataSocket"}
{"level":"ERROR","location":"[get_call:111] fyersModel","message":"HTTPSConnectionPool(host='api-t1.fyers.in', port=443): Max retries exceeded with url: /api/v3/positions (Caused by NewConnectionError('<urllib3.connection.HTTPSConnection object at 0x00000202D4F799D0>: Failed to establish a new connection: [WinError 10060] A connection attempt failed because the connected party did not properly respond after a period of time, or established connection failed because connected host has failed to respond'))","timestamp":"2024-01-15 09:27:40,141+0530","service":"FyersDataSocket"}
{"level":"ERROR","location":"[get_call:111] fyersModel","message":"HTTPSConnectionPool(host='api-t1.fyers.in', port=443): Max retries exceeded with url: /api/v3/positions (Caused by NewConnectionError('<urllib3.connection.HTTPSConnection object at 0x00000202D4F4EE20>: Failed to establish a new connection: [WinError 10060] A connection attempt failed because the connected party did not properly respond after a period of time, or established connection failed because connected host has failed to respond'))","timestamp":"2024-01-15 09:27:42,311+0530","service":"FyersDataSocket"}
{"level":"ERROR","location":"[get_call:111] fyersModel","message":"HTTPSConnectionPool(host='api-t1.fyers.in', port=443): Max retries exceeded with url: /api/v3/positions (Caused by NewConnectionError('<urllib3.connection.HTTPSConnection object at 0x00000202D4F449A0>: Failed to establish a new connection: [WinError 10060] A connection attempt failed because the connected party did not properly respond after a period of time, or established connection failed because connected host has failed to respond'))","timestamp":"2024-01-15 09:27:44,389+0530","service":"FyersDataSocket"}
{"level":"ERROR","location":"[get_call:111] fyersModel","message":"HTTPSConnectionPool(host='api-t1.fyers.in', port=443): Max retries exceeded with url: /api/v3/positions (Caused by NewConnectionError('<urllib3.connection.HTTPSConnection object at 0x00000202D2D6B6D0>: Failed to establish a new connection: [WinError 10060] A connection attempt failed because the connected party did not properly respond after a period of time, or established connection failed because connected host has failed to respond'))","timestamp":"2024-01-15 09:27:46,445+0530","service":"FyersDataSocket"}
{"level":"ERROR","location":"[get_call:111] fyersModel","message":"HTTPSConnectionPool(host='api-t1.fyers.in', port=443): Max retries exceeded with url: /api/v3/positions (Caused by NewConnectionError('<urllib3.connection.HTTPSConnection object at 0x00000202D2D61A60>: Failed to establish a new connection: [WinError 10060] A connection attempt failed because the connected party did not properly respond after a period of time, or established connection failed because connected host has failed to respond'))","timestamp":"2024-01-15 09:27:48,049+0530","service":"FyersDataSocket"}
{"level":"ERROR","location":"[get_call:111] fyersModel","message":"HTTPSConnectionPool(host='api-t1.fyers.in', port=443): Max retries exceeded with url: /api/v3/positions (Caused by NewConnectionError('<urllib3.connection.HTTPSConnection object at 0x00000202D4F7EC70>: Failed to establish a new connection: [WinError 10060] A connection attempt failed because the connected party did not properly respond after a period of time, or established connection failed because connected host has failed to respond'))","timestamp":"2024-01-15 09:27:50,429+0530","service":"FyersDataSocket"}
{"level":"ERROR","location":"[get_call:111] fyersModel","message":"HTTPSConnectionPool(host='api-t1.fyers.in', port=443): Max retries exceeded with url: /api/v3/positions (Caused by NewConnectionError('<urllib3.connection.HTTPSConnection object at 0x00000202D4F88B20>: Failed to establish a new connection: [WinError 10060] A connection attempt failed because the connected party did not properly respond after a period of time, or established connection failed because connected host has failed to respond'))","timestamp":"2024-01-15 09:27:52,128+0530","service":"FyersDataSocket"}
{"level":"ERROR","location":"[get_call:111] fyersModel","message":"HTTPSConnectionPool(host='api-t1.fyers.in', port=443): Max retries exceeded with url: /api/v3/positions (Caused by NewConnectionError('<urllib3.connection.HTTPSConnection object at 0x00000202D4F929A0>: Failed to establish a new connection: [WinError 10060] A connection attempt failed because the connected party did not properly respond after a period of time, or established connection failed because connected host has failed to respond'))","timestamp":"2024-01-15 09:27:54,144+0530","service":"FyersDataSocket"}
{"level":"ERROR","location":"[get_call:111] fyersModel","message":"HTTPSConnectionPool(host='api-t1.fyers.in', port=443): Max retries exceeded with url: /api/v3/positions (Caused by NewConnectionError('<urllib3.connection.HTTPSConnection object at 0x00000202D4F97820>: Failed to establish a new connection: [WinError 10060] A connection attempt failed because the connected party did not properly respond after a period of time, or established connection failed because connected host has failed to respond'))","timestamp":"2024-01-15 09:27:56,321+0530","service":"FyersDataSocket"}
{"level":"ERROR","location":"[get_call:111] fyersModel","message":"HTTPSConnectionPool(host='api-t1.fyers.in', port=443): Max retries exceeded with url: /api/v3/positions (Caused by NewConnectionError('<urllib3.connection.HTTPSConnection object at 0x00000202D4F9C6A0>: Failed to establish a new connection: [WinError 10060] A connection attempt failed because the connected party did not properly respond after a period of time, or established connection failed because connected host has failed to respond'))","timestamp":"2024-01-15 09:27:58,235+0530","service":"FyersDataSocket"}
{"level":"ERROR","location":"[get_call:111] fyersModel","message":"HTTPSConnectionPool(host='api-t1.fyers.in', port=443): Max retries exceeded with url: /api/v3/positions (Caused by NewConnectionError('<urllib3.connection.HTTPSConnection object at 0x00000202D6075520>: Failed to establish a new connection: [WinError 10060] A connection attempt failed because the connected party did not properly respond after a period of time, or established connection failed because connected host has failed to respond'))","timestamp":"2024-01-15 09:28:00,248+0530","service":"FyersDataSocket"}
{"level":"ERROR","location":"[get_call:111] fyersModel","message":"HTTPSConnectionPool(host='api-t1.fyers.in', port=443): Max retries exceeded with url: /api/v3/positions (Caused by NewConnectionError('<urllib3.connection.HTTPSConnection object at 0x00000202D607E400>: Failed to establish a new connection: [WinError 10060] A connection attempt failed because the connected party did not properly respond after a period of time, or established connection failed because connected host has failed to respond'))","timestamp":"2024-01-15 09:28:02,370+0530","service":"FyersDataSocket"}
{"level":"ERROR","location":"[get_call:111] fyersModel","message":"HTTPSConnectionPool(host='api-t1.fyers.in', port=443): Max retries exceeded with url: /api/v3/positions (Caused by NewConnectionError('<urllib3.connection.HTTPSConnection object at 0x00000202D6086250>: Failed to establish a new connection: [WinError 10060] A connection attempt failed because the connected party did not properly respond after a period of time, or established connection failed because connected host has failed to respond'))","timestamp":"2024-01-15 09:28:04,278+0530","service":"FyersDataSocket"}
{"level":"ERROR","location":"[get_call:111] fyersModel","message":"HTTPSConnectionPool(host='api-t1.fyers.in', port=443): Max retries exceeded with url: /api/v3/positions (Caused by NewConnectionError('<urllib3.connection.HTTPSConnection object at 0x00000202D608D0D0>: Failed to establish a new connection: [WinError 10060] A connection attempt failed because the connected party did not properly respond after a period of time, or established connection failed because connected host has failed to respond'))","timestamp":"2024-01-15 09:28:06,289+0530","service":"FyersDataSocket"}
{"level":"ERROR","location":"[get_call:111] fyersModel","message":"('Connection aborted.', RemoteDisconnected('Remote end closed connection without response'))","timestamp":"2024-01-15 09:28:06,864+0530","service":"FyersDataSocket"}
{"level":"ERROR","location":"[get_call:111] fyersModel","message":"HTTPSConnectionPool(host='api-t1.fyers.in', port=443): Max retries exceeded with url: /api/v3/positions (Caused by NewConnectionError('<urllib3.connection.HTTPSConnection object at 0x00000202D608DF40>: Failed to establish a new connection: [WinError 10060] A connection attempt failed because the connected party did not properly respond after a period of time, or established connection failed because connected host has failed to respond'))","timestamp":"2024-01-15 09:28:08,299+0530","service":"FyersDataSocket"}
{"level":"ERROR","location":"[get_call:111] fyersModel","message":"HTTPSConnectionPool(host='api-t1.fyers.in', port=443): Max retries exceeded with url: /api/v3/positions (Caused by NewConnectionError('<urllib3.connection.HTTPSConnection object at 0x00000202D6094D90>: Failed to establish a new connection: [WinError 10060] A connection attempt failed because the connected party did not properly respond after a period of time, or established connection failed because connected host has failed to respond'))","timestamp":"2024-01-15 09:28:10,340+0530","service":"FyersDataSocket"}
{"level":"ERROR","location":"[get_call:111] fyersModel","message":"HTTPSConnectionPool(host='api-t1.fyers.in', port=443): Max retries exceeded with url: /api/v3/positions (Caused by NewConnectionError('<urllib3.connection.HTTPSConnection object at 0x00000202D609EC70>: Failed to establish a new connection: [WinError 10060] A connection attempt failed because the connected party did not properly respond after a period of time, or established connection failed because connected host has failed to respond'))","timestamp":"2024-01-15 09:28:12,290+0530","service":"FyersDataSocket"}
{"level":"ERROR","location":"[get_call:111] fyersModel","message":"('Connection aborted.', ConnectionResetError(10054, 'An existing connection was forcibly closed by the remote host', None, 10054, None))","timestamp":"2024-01-15 09:28:14,166+0530","service":"FyersDataSocket"}
{"level":"ERROR","location":"[get_call:111] fyersModel","message":"('Connection aborted.', ConnectionResetError(10054, 'An existing connection was forcibly closed by the remote host', None, 10054, None))","timestamp":"2024-01-15 09:28:14,167+0530","service":"FyersDataSocket"}
{"level":"ERROR","location":"[get_call:111] fyersModel","message":"('Connection aborted.', ConnectionResetError(10054, 'An existing connection was forcibly closed by the remote host', None, 10054, None))","timestamp":"2024-01-15 09:28:14,168+0530","service":"FyersDataSocket"}
{"level":"ERROR","location":"[get_call:111] fyersModel","message":"('Connection aborted.', ConnectionResetError(10054, 'An existing connection was forcibly closed by the remote host', None, 10054, None))","timestamp":"2024-01-15 09:28:14,169+0530","service":"FyersDataSocket"}
{"level":"ERROR","location":"[get_call:111] fyersModel","message":"('Connection aborted.', ConnectionResetError(10054, 'An existing connection was forcibly closed by the remote host', None, 10054, None))","timestamp":"2024-01-15 09:28:14,169+0530","service":"FyersDataSocket"}
{"level":"ERROR","location":"[get_call:111] fyersModel","message":"('Connection aborted.', ConnectionResetError(10054, 'An existing connection was forcibly closed by the remote host', None, 10054, None))","timestamp":"2024-01-15 09:28:14,169+0530","service":"FyersDataSocket"}
{"level":"ERROR","location":"[get_call:111] fyersModel","message":"('Connection aborted.', ConnectionResetError(10054, 'An existing connection was forcibly closed by the remote host', None, 10054, None))","timestamp":"2024-01-15 09:28:14,185+0530","service":"FyersDataSocket"}
{"level":"ERROR","location":"[get_call:111] fyersModel","message":"('Connection aborted.', ConnectionResetError(10054, 'An existing connection was forcibly closed by the remote host', None, 10054, None))","timestamp":"2024-01-15 09:28:14,188+0530","service":"FyersDataSocket"}
{"level":"ERROR","location":"[get_call:111] fyersModel","message":"('Connection aborted.', ConnectionResetError(10054, 'An existing connection was forcibly closed by the remote host', None, 10054, None))","timestamp":"2024-01-15 09:28:14,190+0530","service":"FyersDataSocket"}
{"level":"ERROR","location":"[get_call:111] fyersModel","message":"('Connection aborted.', ConnectionResetError(10054, 'An existing connection was forcibly closed by the remote host', None, 10054, None))","timestamp":"2024-01-15 09:28:14,190+0530","service":"FyersDataSocket"}
{"level":"ERROR","location":"[get_call:111] fyersModel","message":"('Connection aborted.', ConnectionResetError(10054, 'An existing connection was forcibly closed by the remote host', None, 10054, None))","timestamp":"2024-01-15 09:28:14,190+0530","service":"FyersDataSocket"}
{"level":"ERROR","location":"[exception:108] fyers_logger","message":"('Connection aborted.', ConnectionResetError(10054, 'An existing connection was forcibly closed by the remote host', None, 10054, None))","timestamp":"2024-01-15 09:28:14,205+0530","service":"FyersDataSocket","exception":"Traceback (most recent call last):\n  File \"E:\\Python\\WorkSpace\\fyers-app-v3\\venv\\lib\\site-packages\\websocket\\_app.py\", line 428, in setSock\n    dispatcher.read(self.sock.sock, read, check)\n  File \"E:\\Python\\WorkSpace\\fyers-app-v3\\venv\\lib\\site-packages\\websocket\\_app.py\", line 99, in read\n    if not read_callback():\n  File \"E:\\Python\\WorkSpace\\fyers-app-v3\\venv\\lib\\site-packages\\websocket\\_app.py\", line 437, in read\n    op_code, frame = self.sock.recv_data_frame(True)\n  File \"E:\\Python\\WorkSpace\\fyers-app-v3\\venv\\lib\\site-packages\\websocket\\_core.py\", line 406, in recv_data_frame\n    frame = self.recv_frame()\n  File \"E:\\Python\\WorkSpace\\fyers-app-v3\\venv\\lib\\site-packages\\websocket\\_core.py\", line 445, in recv_frame\n    return self.frame_buffer.recv_frame()\n  File \"E:\\Python\\WorkSpace\\fyers-app-v3\\venv\\lib\\site-packages\\websocket\\_abnf.py\", line 338, in recv_frame\n    self.recv_header()\n  File \"E:\\Python\\WorkSpace\\fyers-app-v3\\venv\\lib\\site-packages\\websocket\\_abnf.py\", line 294, in recv_header\n    header = self.recv_strict(2)\n  File \"E:\\Python\\WorkSpace\\fyers-app-v3\\venv\\lib\\site-packages\\websocket\\_abnf.py\", line 373, in recv_strict\n    bytes_ = self.recv(min(16384, shortage))\n  File \"E:\\Python\\WorkSpace\\fyers-app-v3\\venv\\lib\\site-packages\\websocket\\_core.py\", line 529, in _recv\n    return recv(self.sock, bufsize)\n  File \"E:\\Python\\WorkSpace\\fyers-app-v3\\venv\\lib\\site-packages\\websocket\\_socket.py\", line 108, in recv\n    bytes_ = _recv()\n  File \"E:\\Python\\WorkSpace\\fyers-app-v3\\venv\\lib\\site-packages\\websocket\\_socket.py\", line 87, in _recv\n    return sock.recv(bufsize)\n  File \"C:\\Users\\arun.jose\\AppData\\Local\\Programs\\Python\\Python39\\lib\\ssl.py\", line 1226, in recv\n    return self.read(buflen)\n  File \"C:\\Users\\arun.jose\\AppData\\Local\\Programs\\Python\\Python39\\lib\\ssl.py\", line 1101, in read\n    return self._sslobj.read(len)\nConnectionResetError: [WinError 10054] An existing connection was forcibly closed by the remote host\n\nDuring handling of the above exception, another exception occurred:\n\nTraceback (most recent call last):\n  File \"E:\\Python\\WorkSpace\\fyers-app-v3\\venv\\lib\\site-packages\\urllib3\\connectionpool.py\", line 703, in urlopen\n    httplib_response = self._make_request(\n  File \"E:\\Python\\WorkSpace\\fyers-app-v3\\venv\\lib\\site-packages\\urllib3\\connectionpool.py\", line 386, in _make_request\n    self._validate_conn(conn)\n  File \"E:\\Python\\WorkSpace\\fyers-app-v3\\venv\\lib\\site-packages\\urllib3\\connectionpool.py\", line 1042, in _validate_conn\n    conn.connect()\n  File \"E:\\Python\\WorkSpace\\fyers-app-v3\\venv\\lib\\site-packages\\urllib3\\connection.py\", line 414, in connect\n    self.sock = ssl_wrap_socket(\n  File \"E:\\Python\\WorkSpace\\fyers-app-v3\\venv\\lib\\site-packages\\urllib3\\util\\ssl_.py\", line 449, in ssl_wrap_socket\n    ssl_sock = _ssl_wrap_socket_impl(\n  File \"E:\\Python\\WorkSpace\\fyers-app-v3\\venv\\lib\\site-packages\\urllib3\\util\\ssl_.py\", line 493, in _ssl_wrap_socket_impl\n    return ssl_context.wrap_socket(sock, server_hostname=server_hostname)\n  File \"C:\\Users\\arun.jose\\AppData\\Local\\Programs\\Python\\Python39\\lib\\ssl.py\", line 500, in wrap_socket\n    return self.sslsocket_class._create(\n  File \"C:\\Users\\arun.jose\\AppData\\Local\\Programs\\Python\\Python39\\lib\\ssl.py\", line 1040, in _create\n    self.do_handshake()\n  File \"C:\\Users\\arun.jose\\AppData\\Local\\Programs\\Python\\Python39\\lib\\ssl.py\", line 1309, in do_handshake\n    self._sslobj.do_handshake()\nConnectionResetError: [WinError 10054] An existing connection was forcibly closed by the remote host\n\nDuring handling of the above exception, another exception occurred:\n\nTraceback (most recent call last):\n  File \"E:\\Python\\WorkSpace\\fyers-app-v3\\venv\\lib\\site-packages\\requests\\adapters.py\", line 486, in send\n    resp = conn.urlopen(\n  File \"E:\\Python\\WorkSpace\\fyers-app-v3\\venv\\lib\\site-packages\\urllib3\\connectionpool.py\", line 787, in urlopen\n    retries = retries.increment(\n  File \"E:\\Python\\WorkSpace\\fyers-app-v3\\venv\\lib\\site-packages\\urllib3\\util\\retry.py\", line 550, in increment\n    raise six.reraise(type(error), error, _stacktrace)\n  File \"E:\\Python\\WorkSpace\\fyers-app-v3\\venv\\lib\\site-packages\\urllib3\\packages\\six.py\", line 769, in reraise\n    raise value.with_traceback(tb)\n  File \"E:\\Python\\WorkSpace\\fyers-app-v3\\venv\\lib\\site-packages\\urllib3\\connectionpool.py\", line 703, in urlopen\n    httplib_response = self._make_request(\n  File \"E:\\Python\\WorkSpace\\fyers-app-v3\\venv\\lib\\site-packages\\urllib3\\connectionpool.py\", line 386, in _make_request\n    self._validate_conn(conn)\n  File \"E:\\Python\\WorkSpace\\fyers-app-v3\\venv\\lib\\site-packages\\urllib3\\connectionpool.py\", line 1042, in _validate_conn\n    conn.connect()\n  File \"E:\\Python\\WorkSpace\\fyers-app-v3\\venv\\lib\\site-packages\\urllib3\\connection.py\", line 414, in connect\n    self.sock = ssl_wrap_socket(\n  File \"E:\\Python\\WorkSpace\\fyers-app-v3\\venv\\lib\\site-packages\\urllib3\\util\\ssl_.py\", line 449, in ssl_wrap_socket\n    ssl_sock = _ssl_wrap_socket_impl(\n  File \"E:\\Python\\WorkSpace\\fyers-app-v3\\venv\\lib\\site-packages\\urllib3\\util\\ssl_.py\", line 493, in _ssl_wrap_socket_impl\n    return ssl_context.wrap_socket(sock, server_hostname=server_hostname)\n  File \"C:\\Users\\arun.jose\\AppData\\Local\\Programs\\Python\\Python39\\lib\\ssl.py\", line 500, in wrap_socket\n    return self.sslsocket_class._create(\n  File \"C:\\Users\\arun.jose\\AppData\\Local\\Programs\\Python\\Python39\\lib\\ssl.py\", line 1040, in _create\n    self.do_handshake()\n  File \"C:\\Users\\arun.jose\\AppData\\Local\\Programs\\Python\\Python39\\lib\\ssl.py\", line 1309, in do_handshake\n    self._sslobj.do_handshake()\nurllib3.exceptions.ProtocolError: ('Connection aborted.', ConnectionResetError(10054, 'An existing connection was forcibly closed by the remote host', None, 10054, None))\n\nDuring handling of the above exception, another exception occurred:\n\nTraceback (most recent call last):\n  File \"E:\\Python\\WorkSpace\\fyers-app-v3\\venv\\lib\\site-packages\\fyers_apiv3\\FyersWebsocket\\data_ws.py\", line 65, in symbol_to_hsmtoken\n    response = requests.get(\n  File \"E:\\Python\\WorkSpace\\fyers-app-v3\\venv\\lib\\site-packages\\requests\\api.py\", line 73, in get\n    return request(\"get\", url, params=params, **kwargs)\n  File \"E:\\Python\\WorkSpace\\fyers-app-v3\\venv\\lib\\site-packages\\requests\\api.py\", line 59, in request\n    return session.request(method=method, url=url, **kwargs)\n  File \"E:\\Python\\WorkSpace\\fyers-app-v3\\venv\\lib\\site-packages\\requests\\sessions.py\", line 589, in request\n    resp = self.send(prep, **send_kwargs)\n  File \"E:\\Python\\WorkSpace\\fyers-app-v3\\venv\\lib\\site-packages\\requests\\sessions.py\", line 703, in send\n    r = adapter.send(request, **kwargs)\n  File \"E:\\Python\\WorkSpace\\fyers-app-v3\\venv\\lib\\site-packages\\requests\\adapters.py\", line 501, in send\n    raise ConnectionError(err, request=request)\nrequests.exceptions.ConnectionError: ('Connection aborted.', ConnectionResetError(10054, 'An existing connection was forcibly closed by the remote host', None, 10054, None))","exception_name":"ConnectionError"}
{"level":"ERROR","location":"[get_call:111] fyersModel","message":"('Connection aborted.', ConnectionResetError(10054, 'An existing connection was forcibly closed by the remote host', None, 10054, None))","timestamp":"2024-01-15 09:28:14,205+0530","service":"FyersDataSocket"}
{"level":"ERROR","location":"[get_call:111] fyersModel","message":"('Connection aborted.', ConnectionResetError(10054, 'An existing connection was forcibly closed by the remote host', None, 10054, None))","timestamp":"2024-01-15 09:28:14,205+0530","service":"FyersDataSocket"}
{"level":"ERROR","location":"[get_call:111] fyersModel","message":"('Connection aborted.', ConnectionResetError(10054, 'An existing connection was forcibly closed by the remote host', None, 10054, None))","timestamp":"2024-01-15 09:28:14,205+0530","service":"FyersDataSocket"}
{"level":"ERROR","location":"[get_call:111] fyersModel","message":"('Connection aborted.', ConnectionResetError(10054, 'An existing connection was forcibly closed by the remote host', None, 10054, None))","timestamp":"2024-01-15 09:28:14,205+0530","service":"FyersDataSocket"}
{"level":"ERROR","location":"[get_call:111] fyersModel","message":"('Connection aborted.', ConnectionResetError(10054, 'An existing connection was forcibly closed by the remote host', None, 10054, None))","timestamp":"2024-01-15 09:28:14,205+0530","service":"FyersDataSocket"}
{"level":"ERROR","location":"[get_call:111] fyersModel","message":"('Connection aborted.', ConnectionResetError(10054, 'An existing connection was forcibly closed by the remote host', None, 10054, None))","timestamp":"2024-01-15 09:28:14,205+0530","service":"FyersDataSocket"}
{"level":"ERROR","location":"[get_call:111] fyersModel","message":"('Connection aborted.', ConnectionResetError(10054, 'An existing connection was forcibly closed by the remote host', None, 10054, None))","timestamp":"2024-01-15 09:28:14,205+0530","service":"FyersDataSocket"}
{"level":"ERROR","location":"[exception:108] fyers_logger","message":"'NoneType' object is not subscriptable","timestamp":"2024-01-15 09:28:14,413+0530","service":"FyersDataSocket","exception":"Traceback (most recent call last):\n  File \"E:\\Python\\WorkSpace\\fyers-app-v3\\venv\\lib\\site-packages\\websocket\\_app.py\", line 428, in setSock\n    dispatcher.read(self.sock.sock, read, check)\n  File \"E:\\Python\\WorkSpace\\fyers-app-v3\\venv\\lib\\site-packages\\websocket\\_app.py\", line 99, in read\n    if not read_callback():\n  File \"E:\\Python\\WorkSpace\\fyers-app-v3\\venv\\lib\\site-packages\\websocket\\_app.py\", line 437, in read\n    op_code, frame = self.sock.recv_data_frame(True)\n  File \"E:\\Python\\WorkSpace\\fyers-app-v3\\venv\\lib\\site-packages\\websocket\\_core.py\", line 406, in recv_data_frame\n    frame = self.recv_frame()\n  File \"E:\\Python\\WorkSpace\\fyers-app-v3\\venv\\lib\\site-packages\\websocket\\_core.py\", line 445, in recv_frame\n    return self.frame_buffer.recv_frame()\n  File \"E:\\Python\\WorkSpace\\fyers-app-v3\\venv\\lib\\site-packages\\websocket\\_abnf.py\", line 338, in recv_frame\n    self.recv_header()\n  File \"E:\\Python\\WorkSpace\\fyers-app-v3\\venv\\lib\\site-packages\\websocket\\_abnf.py\", line 294, in recv_header\n    header = self.recv_strict(2)\n  File \"E:\\Python\\WorkSpace\\fyers-app-v3\\venv\\lib\\site-packages\\websocket\\_abnf.py\", line 373, in recv_strict\n    bytes_ = self.recv(min(16384, shortage))\n  File \"E:\\Python\\WorkSpace\\fyers-app-v3\\venv\\lib\\site-packages\\websocket\\_core.py\", line 529, in _recv\n    return recv(self.sock, bufsize)\n  File \"E:\\Python\\WorkSpace\\fyers-app-v3\\venv\\lib\\site-packages\\websocket\\_socket.py\", line 108, in recv\n    bytes_ = _recv()\n  File \"E:\\Python\\WorkSpace\\fyers-app-v3\\venv\\lib\\site-packages\\websocket\\_socket.py\", line 87, in _recv\n    return sock.recv(bufsize)\n  File \"C:\\Users\\arun.jose\\AppData\\Local\\Programs\\Python\\Python39\\lib\\ssl.py\", line 1226, in recv\n    return self.read(buflen)\n  File \"C:\\Users\\arun.jose\\AppData\\Local\\Programs\\Python\\Python39\\lib\\ssl.py\", line 1101, in read\n    return self._sslobj.read(len)\nConnectionResetError: [WinError 10054] An existing connection was forcibly closed by the remote host\n\nDuring handling of the above exception, another exception occurred:\n\nTraceback (most recent call last):\n  File \"E:\\Python\\WorkSpace\\fyers-app-v3\\venv\\lib\\site-packages\\fyers_apiv3\\FyersWebsocket\\data_ws.py\", line 1334, in __symbol_conversion\n    symbol_dict.update(symbol_dict, **symbol_value[0])\nTypeError: 'NoneType' object is not subscriptable","exception_name":"TypeError"}
{"level":"ERROR","location":"[get_call:111] fyersModel","message":"('Connection aborted.', ConnectionResetError(10054, 'An existing connection was forcibly closed by the remote host', None, 10054, None))","timestamp":"2024-01-15 09:28:31,395+0530","service":"FyersDataSocket"}
{"level":"ERROR","location":"[get_call:111] fyersModel","message":"('Connection aborted.', ConnectionResetError(10054, 'An existing connection was forcibly closed by the remote host', None, 10054, None))","timestamp":"2024-01-15 09:28:33,613+0530","service":"FyersDataSocket"}
{"level":"ERROR","location":"[get_call:111] fyersModel","message":"('Connection aborted.', ConnectionResetError(10054, 'An existing connection was forcibly closed by the remote host', None, 10054, None))","timestamp":"2024-01-15 09:28:45,233+0530","service":"FyersDataSocket"}
{"level":"ERROR","location":"[get_call:111] fyersModel","message":"('Connection aborted.', ConnectionResetError(10054, 'An existing connection was forcibly closed by the remote host', None, 10054, None))","timestamp":"2024-01-15 09:29:23,805+0530","service":"FyersDataSocket"}
{"level":"ERROR","location":"[get_call:111] fyersModel","message":"HTTPSConnectionPool(host='api-t1.fyers.in', port=443): Max retries exceeded with url: /api/v3/positions (Caused by NewConnectionError('<urllib3.connection.HTTPSConnection object at 0x00000202D4F729D0>: Failed to establish a new connection: [Errno 11001] getaddrinfo failed'))","timestamp":"2024-01-15 09:29:34,738+0530","service":"FyersDataSocket"}
{"level":"ERROR","location":"[get_call:111] fyersModel","message":"('Connection aborted.', ConnectionAbortedError(10053, 'An established connection was aborted by the software in your host machine', None, 10053, None))","timestamp":"2024-01-15 09:29:35,091+0530","service":"FyersDataSocket"}
{"level":"ERROR","location":"[get_call:111] fyersModel","message":"('Connection aborted.', ConnectionAbortedError(10053, 'An established connection was aborted by the software in your host machine', None, 10053, None))","timestamp":"2024-01-15 09:29:35,091+0530","service":"FyersDataSocket"}
{"level":"ERROR","location":"[get_call:111] fyersModel","message":"HTTPSConnectionPool(host='api-t1.fyers.in', port=443): Max retries exceeded with url: /api/v3/positions (Caused by NewConnectionError('<urllib3.connection.HTTPSConnection object at 0x00000202D4F974F0>: Failed to establish a new connection: [WinError 10051] A socket operation was attempted to an unreachable network'))","timestamp":"2024-01-15 09:29:35,107+0530","service":"FyersDataSocket"}
{"level":"ERROR","location":"[exception:108] fyers_logger","message":"0","timestamp":"2024-01-15 09:36:35,071+0530","service":"FyersDataSocket","exception":"Traceback (most recent call last):\n  File \"E:\\Python\\WorkSpace\\fyers-app-v3\\venv\\lib\\site-packages\\fyers_apiv3\\FyersWebsocket\\data_ws.py\", line 1425, in On_message\n    self.OnMessage(message)\n  File \"E:\\Python\\WorkSpace\\fyers-app-v3\\main1.py\", line 336, in onmessage\n    LTP_DICT.update({message[0][\"symbol\"]: message[0][\"ltp\"]})\nKeyError: 0","exception_name":"KeyError"}
{"level":"ERROR","location":"[exception:108] fyers_logger","message":"0","timestamp":"2024-01-15 09:36:35,087+0530","service":"FyersDataSocket","exception":"Traceback (most recent call last):\n  File \"E:\\Python\\WorkSpace\\fyers-app-v3\\venv\\lib\\site-packages\\fyers_apiv3\\FyersWebsocket\\data_ws.py\", line 1425, in On_message\n    self.OnMessage(message)\n  File \"E:\\Python\\WorkSpace\\fyers-app-v3\\main1.py\", line 336, in onmessage\n    LTP_DICT.update({message[0][\"symbol\"]: message[0][\"ltp\"]})\nKeyError: 0","exception_name":"KeyError"}
{"level":"ERROR","location":"[exception:108] fyers_logger","message":"0","timestamp":"2024-01-15 09:44:46,893+0530","service":"FyersDataSocket","exception":"Traceback (most recent call last):\n  File \"E:\\Python\\WorkSpace\\fyers-app-v3\\venv\\lib\\site-packages\\fyers_apiv3\\FyersWebsocket\\data_ws.py\", line 1425, in On_message\n    self.OnMessage(message)\n  File \"E:\\Python\\WorkSpace\\fyers-app-v3\\main1.py\", line 337, in onmessage\n    LTP_DICT.update({message[0][\"symbol\"]: message[0][\"ltp\"]})\nKeyError: 0","exception_name":"KeyError"}
{"level":"ERROR","location":"[exception:108] fyers_logger","message":"0","timestamp":"2024-01-15 09:44:46,893+0530","service":"FyersDataSocket","exception":"Traceback (most recent call last):\n  File \"E:\\Python\\WorkSpace\\fyers-app-v3\\venv\\lib\\site-packages\\fyers_apiv3\\FyersWebsocket\\data_ws.py\", line 1425, in On_message\n    self.OnMessage(message)\n  File \"E:\\Python\\WorkSpace\\fyers-app-v3\\main1.py\", line 337, in onmessage\n    LTP_DICT.update({message[0][\"symbol\"]: message[0][\"ltp\"]})\nKeyError: 0","exception_name":"KeyError"}
{"level":"ERROR","location":"[exception:108] fyers_logger","message":"0","timestamp":"2024-01-15 09:44:47,376+0530","service":"FyersDataSocket","exception":"Traceback (most recent call last):\n  File \"E:\\Python\\WorkSpace\\fyers-app-v3\\venv\\lib\\site-packages\\fyers_apiv3\\FyersWebsocket\\data_ws.py\", line 1425, in On_message\n    self.OnMessage(message)\n  File \"E:\\Python\\WorkSpace\\fyers-app-v3\\main1.py\", line 337, in onmessage\n    LTP_DICT.update({message[0][\"symbol\"]: message[0][\"ltp\"]})\nKeyError: 0","exception_name":"KeyError"}
{"level":"ERROR","location":"[exception:108] fyers_logger","message":"0","timestamp":"2024-01-15 09:44:47,876+0530","service":"FyersDataSocket","exception":"Traceback (most recent call last):\n  File \"E:\\Python\\WorkSpace\\fyers-app-v3\\venv\\lib\\site-packages\\fyers_apiv3\\FyersWebsocket\\data_ws.py\", line 1425, in On_message\n    self.OnMessage(message)\n  File \"E:\\Python\\WorkSpace\\fyers-app-v3\\main1.py\", line 337, in onmessage\n    LTP_DICT.update({message[0][\"symbol\"]: message[0][\"ltp\"]})\nKeyError: 0","exception_name":"KeyError"}
{"level":"ERROR","location":"[exception:108] fyers_logger","message":"0","timestamp":"2024-01-15 09:44:49,018+0530","service":"FyersDataSocket","exception":"Traceback (most recent call last):\n  File \"E:\\Python\\WorkSpace\\fyers-app-v3\\venv\\lib\\site-packages\\fyers_apiv3\\FyersWebsocket\\data_ws.py\", line 1425, in On_message\n    self.OnMessage(message)\n  File \"E:\\Python\\WorkSpace\\fyers-app-v3\\main1.py\", line 337, in onmessage\n    LTP_DICT.update({message[0][\"symbol\"]: message[0][\"ltp\"]})\nKeyError: 0","exception_name":"KeyError"}
{"level":"ERROR","location":"[exception:108] fyers_logger","message":"0","timestamp":"2024-01-15 09:44:49,018+0530","service":"FyersDataSocket","exception":"Traceback (most recent call last):\n  File \"E:\\Python\\WorkSpace\\fyers-app-v3\\venv\\lib\\site-packages\\fyers_apiv3\\FyersWebsocket\\data_ws.py\", line 1425, in On_message\n    self.OnMessage(message)\n  File \"E:\\Python\\WorkSpace\\fyers-app-v3\\main1.py\", line 337, in onmessage\n    LTP_DICT.update({message[0][\"symbol\"]: message[0][\"ltp\"]})\nKeyError: 0","exception_name":"KeyError"}
{"level":"ERROR","location":"[exception:108] fyers_logger","message":"0","timestamp":"2024-01-15 09:44:49,386+0530","service":"FyersDataSocket","exception":"Traceback (most recent call last):\n  File \"E:\\Python\\WorkSpace\\fyers-app-v3\\venv\\lib\\site-packages\\fyers_apiv3\\FyersWebsocket\\data_ws.py\", line 1425, in On_message\n    self.OnMessage(message)\n  File \"E:\\Python\\WorkSpace\\fyers-app-v3\\main1.py\", line 337, in onmessage\n    LTP_DICT.update({message[0][\"symbol\"]: message[0][\"ltp\"]})\nKeyError: 0","exception_name":"KeyError"}
{"level":"ERROR","location":"[exception:108] fyers_logger","message":"0","timestamp":"2024-01-15 09:44:49,386+0530","service":"FyersDataSocket","exception":"Traceback (most recent call last):\n  File \"E:\\Python\\WorkSpace\\fyers-app-v3\\venv\\lib\\site-packages\\fyers_apiv3\\FyersWebsocket\\data_ws.py\", line 1425, in On_message\n    self.OnMessage(message)\n  File \"E:\\Python\\WorkSpace\\fyers-app-v3\\main1.py\", line 337, in onmessage\n    LTP_DICT.update({message[0][\"symbol\"]: message[0][\"ltp\"]})\nKeyError: 0","exception_name":"KeyError"}
{"level":"ERROR","location":"[exception:108] fyers_logger","message":"0","timestamp":"2024-01-15 09:44:49,890+0530","service":"FyersDataSocket","exception":"Traceback (most recent call last):\n  File \"E:\\Python\\WorkSpace\\fyers-app-v3\\venv\\lib\\site-packages\\fyers_apiv3\\FyersWebsocket\\data_ws.py\", line 1425, in On_message\n    self.OnMessage(message)\n  File \"E:\\Python\\WorkSpace\\fyers-app-v3\\main1.py\", line 337, in onmessage\n    LTP_DICT.update({message[0][\"symbol\"]: message[0][\"ltp\"]})\nKeyError: 0","exception_name":"KeyError"}
{"level":"ERROR","location":"[exception:108] fyers_logger","message":"0","timestamp":"2024-01-15 09:44:49,893+0530","service":"FyersDataSocket","exception":"Traceback (most recent call last):\n  File \"E:\\Python\\WorkSpace\\fyers-app-v3\\venv\\lib\\site-packages\\fyers_apiv3\\FyersWebsocket\\data_ws.py\", line 1425, in On_message\n    self.OnMessage(message)\n  File \"E:\\Python\\WorkSpace\\fyers-app-v3\\main1.py\", line 337, in onmessage\n    LTP_DICT.update({message[0][\"symbol\"]: message[0][\"ltp\"]})\nKeyError: 0","exception_name":"KeyError"}
{"level":"ERROR","location":"[exception:108] fyers_logger","message":"0","timestamp":"2024-01-15 09:44:50,393+0530","service":"FyersDataSocket","exception":"Traceback (most recent call last):\n  File \"E:\\Python\\WorkSpace\\fyers-app-v3\\venv\\lib\\site-packages\\fyers_apiv3\\FyersWebsocket\\data_ws.py\", line 1425, in On_message\n    self.OnMessage(message)\n  File \"E:\\Python\\WorkSpace\\fyers-app-v3\\main1.py\", line 337, in onmessage\n    LTP_DICT.update({message[0][\"symbol\"]: message[0][\"ltp\"]})\nKeyError: 0","exception_name":"KeyError"}
{"level":"ERROR","location":"[exception:108] fyers_logger","message":"0","timestamp":"2024-01-15 09:44:50,892+0530","service":"FyersDataSocket","exception":"Traceback (most recent call last):\n  File \"E:\\Python\\WorkSpace\\fyers-app-v3\\venv\\lib\\site-packages\\fyers_apiv3\\FyersWebsocket\\data_ws.py\", line 1425, in On_message\n    self.OnMessage(message)\n  File \"E:\\Python\\WorkSpace\\fyers-app-v3\\main1.py\", line 337, in onmessage\n    LTP_DICT.update({message[0][\"symbol\"]: message[0][\"ltp\"]})\nKeyError: 0","exception_name":"KeyError"}
{"level":"ERROR","location":"[exception:108] fyers_logger","message":"0","timestamp":"2024-01-15 09:44:50,892+0530","service":"FyersDataSocket","exception":"Traceback (most recent call last):\n  File \"E:\\Python\\WorkSpace\\fyers-app-v3\\venv\\lib\\site-packages\\fyers_apiv3\\FyersWebsocket\\data_ws.py\", line 1425, in On_message\n    self.OnMessage(message)\n  File \"E:\\Python\\WorkSpace\\fyers-app-v3\\main1.py\", line 337, in onmessage\n    LTP_DICT.update({message[0][\"symbol\"]: message[0][\"ltp\"]})\nKeyError: 0","exception_name":"KeyError"}
